Workbook

Sheet Catálogo PVP
A1: ITEM | B1: CÓDIGO | C1: CATEGORÍA | D1: DESCRIPCIÓN DEL PRODUCTO | E1: PVP (miles COP) | F1: PVP COP | G1: PVP USD | H1: PREMIUM (PR) | I1: ESTADO
A2: 1 | B2: CO4606 | C2: Cocina (Cookware) | D2: SISTEMA DE COCINA ESENCIAL 5 PIEZAS RP CON RECETARIO Y ROYAL SHINE | E2: 6490 | F2: =E2*1000 -> 6490000 | G2: =IFERROR(F2/'Reglas Comerciales'!$B$5,0) -> 1471.939 | H2: No | I2: Activo
A3: 2 | B3: CO4616 | C3: Cocina (Cookware) | D3: SISTEMA DE COCINA COMPLEMENTARIO 5 PIEZAS RP CON RECETARIO Y ROYAL SHINE | E3: 7990 | F3: =E3*1000 -> 7990000 | G3: =IFERROR(F3/'Reglas Comerciales'!$B$5,0) -> 1812.1407 | H3: No | I3: Activo
A4: 3 | B4: CO4626 | C4: Cocina (Cookware) | D4: SISTEMA DE COCINA CLÁSICO 7 PIEZAS RP CON RECETARIO Y ROYAL SHINE | E4: 9790 | F4: =E4*1000 -> 9790000 | G4: =IFERROR(F4/'Reglas Comerciales'!$B$5,0) -> 2220.3826 | H4: No | I4: Activo
A5: 4 | B5: CO4636 | C5: Cocina (Cookware) | D5: SISTEMA DE COCINA ESPECIAL 8 PIEZAS RP CON RECETARIO Y ROYAL SHINE | E5: 12690 | F5: =E5*1000 -> 12690000 | G5: =IFERROR(F5/'Reglas Comerciales'!$B$5,0) -> 2878.1058 | H5: No | I5: Activo
A6: 5 | B6: CO4646 | C6: Cocina (Cookware) | D6: SISTEMA DE COCINA FAMILIAR 10 PIEZAS RP CON RECETARIO Y ROYAL SHINE | E6: 14990 | F6: =E6*1000 -> 14990000 | G6: =IFERROR(F6/'Reglas Comerciales'!$B$5,0) -> 3399.7483 | H6: No | I6: Activo
A7: 6 | B7: CO4656 | C7: Cocina (Cookware) | D7: SISTEMA DE COCINA PROFESIONAL 15 PIEZAS RP CON RECETARIO Y ROYAL SHINE | E7: 21990 | F7: =E7*1000 -> 21990000 | G7: =IFERROR(F7/'Reglas Comerciales'!$B$5,0) -> 4987.3558 | H7: No | I7: Activo
A8: — | B8: CO4911 | C8: Cocina (Cookware) | D8: ROYAL PRESTIGE MULTIPAN | E8: 4490 | F8: =E8*1000 -> 4490000 | G8: =IFERROR(F8/'Reglas Comerciales'!$B$5,0) -> 1018.3369 | H8: No | I8: Activo
A9: 7 | B9: 1+15 | C9: Combo Cocina | D9: COMBO IDEAL 7 PIEZAS (ESENCIAL + PAELLERA CON TAPA DE 10"/26 CM) | E9: 9290 | F9: =E9*1000 -> 9290000 | G9: =IFERROR(F9/'Reglas Comerciales'!$B$5,0) -> 2106.9821 | H9: No | I9: Activo
A10: 8 | B10: 2+15 | C10: Combo Cocina | D10: COMBO UTILITARIO 7 PIEZAS (COMPLEMENTARIO + PAELLERA CON TAPA DE 10"/26 CM) | E10: 10690 | F10: =E10*1000 -> 10690000 | G10: =IFERROR(F10/'Reglas Comerciales'!$B$5,0) -> 2424.5036 | H10: No | I10: Activo
A11: 9 | B11: 15+23+28 | C11: Combo Cocina | D11: COMBO SÉNIOR 4 PIEZAS (PAELLERA CON TAPA DE 10" + OLLA 2 CUARTOS + TAPA 16 CM) | E11: 5590 | F11: =E11*1000 -> 5590000 | G11: =IFERROR(F11/'Reglas Comerciales'!$B$5,0) -> 1267.8181 | H11: No | I11: Activo
A12: 10 | B12: CO4715 | C12: Cocina (Cookware) | D12: UTENSILIO CON TAPA DE 4 CUARTOS RP | E12: 2960 | F12: =E12*1000 -> 2960000 | G12: =IFERROR(F12/'Reglas Comerciales'!$B$5,0) -> 671.33121 | H12: No | I12: Activo
A13: 11 | B13: CO4725 | C13: Cocina (Cookware) | D13: UTENSILIO CON TAPA DE 8 CUARTOS RP | E13: 3840 | F13: =E13*1000 -> 3840000 | G13: =IFERROR(F13/'Reglas Comerciales'!$B$5,0) -> 870.91616 | H13: No | I13: Activo
A14: 12 | B14: CO9660 | C14: Cocina (Cookware) | D14: UTENSILIO CON TAPA DE 12 CUARTOS | E14: 4300 | F14: =E14*1000 -> 4300000 | G14: =IFERROR(F14/'Reglas Comerciales'!$B$5,0) -> 975.24466 | H14: No | I14: Activo
A15: 13 | B15: CO9675 | C15: Cocina (Cookware) | D15: UTENSILIO CON TAPA DE 20 CUARTOS | E15: 5090 | F15: =E15*1000 -> 5090000 | G15: =IFERROR(F15/'Reglas Comerciales'!$B$5,0) -> 1154.4175 | H15: No | I15: Activo
A16: 14 | B16: CO9680 | C16: Cocina (Cookware) | D16: UTENSILIO CON TAPA DE 30 CUARTOS | E16: 6010 | F16: =E16*1000 -> 6010000 | G16: =IFERROR(F16/'Reglas Comerciales'!$B$5,0) -> 1363.0745 | H16: No | I16: Activo
A17: 15 | B17: CO4760 | C17: Cocina (Cookware) | D17: PAELLERA CON TAPA DE 10" / 25 CM. RP | E17: 2690 | F17: =E17*1000 -> 2690000 | G17: =IFERROR(F17/'Reglas Comerciales'!$B$5,0) -> 610.09492 | H17: No | I17: Activo
A18: 16 | B18: CO4740 | C18: Cocina (Cookware) | D18: PAELLERA CON TAPA DE 14" / 35 CM. RP | E18: 4780 | F18: =E18*1000 -> 4780000 | G18: =IFERROR(F18/'Reglas Comerciales'!$B$5,0) -> 1084.1092 | H18: No | I18: Activo
A19: 17 | B19: CO1253 | C19: Cocina (Cookware) | D19: OLLA A PRESIÓN DE 6 LITROS RP CON RECETARIO | E19: 4890 | F19: =E19*1000 -> 4890000 | G19: =IFERROR(F19/'Reglas Comerciales'!$B$5,0) -> 1109.0573 | H19: No | I19: Activo
A20: 18 | B20: CO1258 | C20: Cocina (Cookware) | D20: OLLA A PRESIÓN DE 10 LITROS RP CON RECETARIO | E20: 5690 | F20: =E20*1000 -> 5690000 | G20: =IFERROR(F20/'Reglas Comerciales'!$B$5,0) -> 1290.4982 | H20: No | I20: Activo
... A84: 82 | B84: ES0133 | C84: Electrodomésticos | D84: ESTUFA DE INDUCCIÓN RP - PRECISION COOK | E84: 6240 | F84: =E84*1000 -> 6240000 | G84: =IFERROR(F84/'Reglas Comerciales'!$B$5,0) -> 1415.2388 | H84: No | I84: Activo
A85: — | B85: ES4200 | C85: Electrodomésticos | D85: RP POWER BLENDER GO PLUS TIPO A (CON BATIDOR Y CEPILLO) | E85: 3490 | F85: =E85*1000 -> 3490000 | G85: =IFERROR(F85/'Reglas Comerciales'!$B$5,0) -> 791.53578 | H85: No | I85: Activo
A86: — | B86: PE0028 | C86: Repuestos Blender | D86: CONJUNTO PICADOR Y TASA BLENDER GO | E86: 990 | F86: =E86*1000 -> 990000 | G86: =IFERROR(F86/'Reglas Comerciales'!$B$5,0) -> 224.53307 | H86: No | I86: Activo
A87: 83 | B87: ES0162 | C87: Electrodomésticos | D87: RP POWER BLENDER MAX 120-127V | E87: 5190 | F87: =E87*1000 -> 5190000 | G87: =IFERROR(F87/'Reglas Comerciales'!$B$5,0) -> 1177.0976 | H87: No | I87: Activo
A88: 84 | B88: PE0010 | C88: Repuestos Blender | D88: JARRA TRITAN COMPLETA POWER BLENDER MAX | E88: 1480 | F88: =E88*1000 -> 1480000 | G88: =IFERROR(F88/'Reglas Comerciales'!$B$5,0) -> 335.6656 | H88: No | I88: Activo
A89: 85 | B89: PE0011 | C89: Repuestos Blender | D89: RP MAX CUP (2) CON ASPAS | E89: 1490 | F89: =E89*1000 -> 1490000 | G89: =IFERROR(F89/'Reglas Comerciales'!$B$5,0) -> 337.93362 | H89: No | I89: Activo
A90: 86 | B90: PE0027 | C90: Repuestos Blender | D90: RP FRESH MAX CO | E90: 1180 | F90: =E90*1000 -> 1180000 | G90: =IFERROR(F90/'Reglas Comerciales'!$B$5,0) -> 267.62528 | H90: No | I90: Activo
A91: 87 | B91: AP2004 | C91: Filtros de Aire | D91: RP FILTRO AIRE PAQ REEMPLAZO EARTH+ | E91: 2320 | F91: =E91*1000 -> 2320000 | G91: =IFERROR(F91/'Reglas Comerciales'!$B$5,0) -> 526.17852 | H91: No | I91: Activo
A92: 88 | B92: WF0417 | C92: Filtración de Agua | D92: SISTEMA DE FILTRACIÓN DE AGUA - FRESCAPURE 3500 | E92: 5690 | F92: =E92*1000 -> 5690000 | G92: =IFERROR(F92/'Reglas Comerciales'!$B$5,0) -> 1290.4982 | H92: No | I92: Activo
A93: 89 | B93: WF0451 | C93: Filtración de Agua | D93: FRESCAPURE CARTUCHO REEMPLAZO 3500 | E93: 1250 | F93: =E93*1000 -> 1250000 | G93: =IFERROR(F93/'Reglas Comerciales'!$B$5,0) -> 283.50136 | H93: No | I93: Activo
A94: 90 | B94: WF0545 | C94: Filtración de Agua | D94: FRESCAPURE CARTUCHO REEMPLAZO 3500 + BATERÍA | E94: 1310 | F94: =E94*1000 -> 1310000 | G94: =IFERROR(F94/'Reglas Comerciales'!$B$5,0) -> 297.10942 | H94: No | I94: Activo
A95: — | B95: WF1210 | C95: Filtración de Agua | D95: FRESCAFLOW 100 – 240B Y MINERALIZADOR RP | E95: 13540 | F95: =E95*1000 -> 13540000 | G95: =IFERROR(F95/'Reglas Comerciales'!$B$5,0) -> 3070.8867 | H95: No | I95: Activo
A96: — | B96: PR2012 | C96: Premium (Accesorios) | D96: FRESCAFLOW PREFILTRO X2 UNIDADES | E96: 1119 | F96: =E96*1000 -> 1119000 | G96: =IFERROR(F96/'Reglas Comerciales'!$B$5,0) -> 253.79041 | H96: Sí | I96: Activo
A97: — | B97: PR2013 | C97: Premium (Accesorios) | D97: FRESCAFLOW FILTRO OSMOSIS INVERSA | E97: 2719 | F97: =E97*1000 -> 2719000 | G97: =IFERROR(F97/'Reglas Comerciales'!$B$5,0) -> 616.67215 | H97: Sí | I97: Activo
A98: — | B98: PR2014 | C98: Premium (Accesorios) | D98: FRESCAFLOW CARTUCHO – MINERALIZADOR Y FILTRO CARBONO | E98: 439 | F98: =E98*1000 -> 439000 | G98: =IFERROR(F98/'Reglas Comerciales'!$B$5,0) -> 99.565676 | H98: Sí | I98: Activo
A99: 91 | B99: PR0709 | C99: Premium (Accesorios) | D99: JUEGO CUBIERTOS AMERICANA 24 PIEZAS | E99: 790 | F99: =E99*1000 -> 790000 | G99: =IFERROR(F99/'Reglas Comerciales'!$B$5,0) -> 179.17286 | H99: Sí | I99: Activo
A100: 92 | B100: SP0081 | C100: Servir / Accesorios Pequeños | D100: JUEGO DE SERVIR DE LUXE 3 PIEZAS | E100: 180 | F100: =E100*1000 -> 180000 | G100: =IFERROR(F100/'Reglas Comerciales'!$B$5,0) -> 40.824195 | H100: No | I100: Activo
A101: 93 | B101: SP0091 | C101: Servir / Accesorios Pequeños | D101: JUEGO DE SERVIR DE LUXE 3 PIEZAS COMPLEMENTARIO | E101: 180 | F101: =E101*1000 -> 180000 | G101: =IFERROR(F101/'Reglas Comerciales'!$B$5,0) -> 40.824195 | H101: No | I101: Activo
A102: 94 | B102: SP0061 | C102: Servir / Accesorios Pequeños | D102: JUEGO DE SERVIR FIESTA 6 PIEZAS | E102: 260 | F102: =E102*1000 -> 260000 | G102: =IFERROR(F102/'Reglas Comerciales'!$B$5,0) -> 58.968282 | H102: No | I102: Activo
A103: 95 | B103: SP0068 | C103: Servir / Accesorios Pequeños | D103: TAZÓN DE 5 CUARTOS DE PARED DOBLE CON TAPA | E103: 460 | F103: =E103*1000 -> 460000 | G103: =IFERROR(F103/'Reglas Comerciales'!$B$5,0) -> 104.3285 | H103: No | I103: Activo
...

Sheet Reglas Comerciales
A1: REGLAS COMERCIALES — PVP 2025.01.01
A3: Concepto | B3: Valor
A4: Unidad PVP en lista | B4: Miles de pesos colombianos (COP)
A5: TRM de la lista (COP/USD) | B5: 4409.15
A6: Descuento máx. en ventas de contado | B6: 0.05
A7: Bono máx. en ventas > $3.000.000 COP | B7: 0.2
A8: Bono máx. en ventas ≤ $3.000.000 COP | B8: 0
A9: Umbral de venta para activar bono | B9: 3000000
A10: Productos recomendados para bono | B10: PREMIUMS (prefijo PR)
A11: Fecha de vigencia | B11: 2025-01-01
A13: NOTAS DEL DOCUMENTO ORIGINAL
A14: 1. La columna P.V.P. está en miles de pesos.
A15: 2. Las ventas de contado podrán tener un descuento máximo del 5%.
A16: 3. Las ventas por valor superior a $3.000.000 podrán tener un bono máximo del 20% en productos de Royal Prestige.
A17: 4. Las ventas por valor inferior a $3.000.000 podrán tener un bono máximo del 0% en productos de Royal Prestige.
A18: 5. Los productos recomendados para el bono de negociación son los PREMIUMS (PR).

Sheet Resumen Categorías
A1: RESUMEN POR CATEGORÍA
A3: Categoría | B3: # Productos | C3: PVP Mínimo (COP) | D3: PVP Máximo (COP) | E3: PVP Promedio (COP)
A4: Cocina (Cookware) | B4: 53 | C4: 630000 | D4: 21990000 | E4: 4451400
A5: Combo Cocina | B5: 3 | C5: 5590000 | D5: 10690000 | E5: 8523333
A6: Cuchillería (Cutlery) | B6: 10 | C6: 560000 | D6: 9390000 | E6: 2312000
A7: Electrodomésticos | B7: 3 | C7: 3490000 | D7: 6240000 | E7: 4973333
A8: Extractor de Jugos | B8: 1 | C8: 8190000 | D8: 8190000 | E8: 8190000
A9: Filtración de Agua | B9: 4 | C9: 1250000 | D9: 13540000 | E9: 5447500
A10: Filtros de Aire | B10: 1 | C10: 2320000 | D10: 2320000 | E10: 2320000
A11: Premium (Accesorios) | B11: 19 | C11: 439000 | D11: 3810000 | E11: 1116158
A12: Repuestos Blender | B12: 4 | C12: 990000 | D12: 1490000 | E12: 1285000
A13: Servir / Accesorios Pequeños | B13: 30 | C13: 70000 | D13: 630000 | E13: 299667
A14: TOTAL | B14: =SUM(B4:B13) -> 128
